package day10;
import java.util.Random;
class TestException extends Exception {
	TestException(String message){
		super(message); 
	}
}
public class ExceptionTest3 {
	public static void main(String[] args)  {
		System.out.println("main()수행시작");
		a();
		System.out.println("main()수행종료");
	}
	static void a()  {
		System.out.println("a()수행시작");
		try {
			b();
		} catch (TestException e){	
			System.out.println("오류 발생 : "+e.getMessage());
			return; // a() 수행종료를 출력하지않고 main으로 돌아감.
		}
		System.out.println("a()수행종료");
	}
	static void b() throws TestException {
		System.out.println("b()수행시작");
		c();
		System.out.println("b()수행종료");
	}
	static void c() throws TestException {
		System.out.println("c()수행시작");
		boolean flag = new Random().nextBoolean();
		if(flag){
			throw new TestException("<<:::::테스트로 예외발생시킴:::::>>"); //error message가 된다 -> TestException 생성자 초기화를 해뒀음
		}else {
			System.out.println("ㅋㅋㅋㅋ");
		}	
		System.out.println("c()수행종료");
	}	
}








